<?xml version="1.0" encoding="utf-8"?>
<!-- =================================================================================== -->
<!-- |    This document was autogenerated by xacro from panda_arm_hand.urdf.xacro      | -->
<!-- |    EDITING THIS FILE BY HAND IS NOT RECOMMENDED                                 | -->
<!-- =================================================================================== -->
<robot name="panda">
  <link name="panda_link0">
    <visual>
      <geometry>
        <mesh filename="package://pybullet_simulator/robots/franka/urdf/meshes/visual/link0.dae"/>
      </geometry>
    </visual>
    <collision>
      <geometry>
        <mesh filename="package://pybullet_simulator/robots/franka/urdf/meshes/visual/link0.dae"/>
      </geometry>
    </collision>
  </link>

  <link name="panda_link1">
    <visual>
      <geometry>
        <mesh filename="package://pybullet_simulator/robots/franka/urdf/meshes/visual/link1.dae"/>
      </geometry>
    </visual>
    <collision>
      <geometry>
        <mesh filename="package://pybullet_simulator/robots/franka/urdf/meshes/visual/link1.dae"/>
      </geometry>
    </collision>
  </link>

  <joint name="panda_joint1" type="revolute">
    <safety_controller k_position="100.0" k_velocity="40.0" soft_lower_limit="-2.8973" soft_upper_limit="2.8973"/>
    <origin rpy="0 0 0" xyz="0 0 0.333"/>
    <parent link="panda_link0"/>
    <child link="panda_link1"/>
    <axis xyz="0 0 1"/>
    <limit effort="87" lower="-2.8973" upper="2.8973" velocity="2.1750"/>
  </joint>

  <link name="panda_link2">
    <visual>
      <geometry>
        <mesh filename="package://pybullet_simulator/robots/franka/urdf/meshes/visual/link2.dae"/>
      </geometry>
    </visual>
    <collision>
      <geometry>
        <mesh filename="package://pybullet_simulator/robots/franka/urdf/meshes/visual/link2.dae"/>
      </geometry>
    </collision>
  </link>

  <joint name="panda_joint2" type="revolute">
    <safety_controller k_position="100.0" k_velocity="40.0" soft_lower_limit="-1.7628" soft_upper_limit="1.7628"/>
    <origin rpy="-1.57079632679 0 0" xyz="0 0 0"/>
    <parent link="panda_link1"/>
    <child link="panda_link2"/>
    <axis xyz="0 0 1"/>
    <limit effort="87" lower="-1.7628" upper="1.7628" velocity="2.1750"/>
  </joint>
  <link name="panda_link3">
    <visual>
      <geometry>
        <mesh filename="package://pybullet_simulator/robots/franka/urdf/meshes/visual/link3.dae"/>
      </geometry>
    </visual>
    <collision>
      <geometry>
        <mesh filename="package://pybullet_simulator/robots/franka/urdf/meshes/visual/link3.dae"/>
      </geometry>
    </collision>
  </link>

  <joint name="panda_joint3" type="revolute">
    <safety_controller k_position="100.0" k_velocity="40.0" soft_lower_limit="-2.8973" soft_upper_limit="2.8973"/>
    <origin rpy="1.57079632679 0 0" xyz="0 -0.316 0"/>
    <parent link="panda_link2"/>
    <child link="panda_link3"/>
    <axis xyz="0 0 1"/>
    <limit effort="87" lower="-2.8973" upper="2.8973" velocity="2.1750"/>
  </joint>
  <link name="panda_link4">
    <visual>
      <geometry>
        <mesh filename="package://pybullet_simulator/robots/franka/urdf/meshes/visual/link4.dae"/>
      </geometry>
    </visual>
    <collision>
      <geometry>
        <mesh filename="package://pybullet_simulator/robots/franka/urdf/meshes/visual/link4.dae"/>
      </geometry>
    </collision>
  </link>

  <joint name="panda_joint4" type="revolute">
    <safety_controller k_position="100.0" k_velocity="40.0" soft_lower_limit="-3.0718" soft_upper_limit="-0.0698"/>
    <origin rpy="1.57079632679 0 0" xyz="0.0825 0 0"/>
    <parent link="panda_link3"/>
    <child link="panda_link4"/>
    <axis xyz="0 0 1"/>
    <limit effort="87" lower="-3.0718" upper="-0.0698" velocity="2.1750"/>
  </joint>

  <link name="panda_link5">
    <visual>
      <geometry>
        <mesh filename="package://pybullet_simulator/robots/franka/urdf/meshes/visual/link5.dae"/>
      </geometry>
    </visual>
    <collision>
      <geometry>
        <mesh filename="package://pybullet_simulator/robots/franka/urdf/meshes/visual/link5.dae"/>
      </geometry>
    </collision>
  </link>

  <joint name="panda_joint5" type="revolute">
    <safety_controller k_position="100.0" k_velocity="40.0" soft_lower_limit="-2.8973" soft_upper_limit="2.8973"/>
    <origin rpy="-1.57079632679 0 0" xyz="-0.0825 0.384 0"/>
    <parent link="panda_link4"/>
    <child link="panda_link5"/>
    <axis xyz="0 0 1"/>
    <limit effort="12" lower="-2.8973" upper="2.8973" velocity="2.6100"/>
  </joint>

  <link name="panda_link6">
    <visual>
      <geometry>
        <mesh filename="package://pybullet_simulator/robots/franka/urdf/meshes/visual/link6.dae"/>
      </geometry>
    </visual>
    <collision>
      <geometry>
        <mesh filename="package://pybullet_simulator/robots/franka/urdf/meshes/visual/link6.dae"/>
      </geometry>
    </collision>
  </link>

  <joint name="panda_joint6" type="revolute">
    <safety_controller k_position="100.0" k_velocity="40.0" soft_lower_limit="-0.0175" soft_upper_limit="3.7525"/>
    <origin rpy="1.57079632679 0 0" xyz="0 0 0"/>
    <parent link="panda_link5"/>
    <child link="panda_link6"/>
    <axis xyz="0 0 1"/>
    <limit effort="12" lower="-0.0175" upper="3.7525" velocity="2.6100"/>
  </joint>

  <link name="panda_link7">
    <visual>
      <geometry>
        <mesh filename="package://pybullet_simulator/robots/franka/urdf/meshes/visual/link7.dae"/>
      </geometry>
    </visual>
    <collision>
      <geometry>
        <mesh filename="package://pybullet_simulator/robots/franka/urdf/meshes/visual/link7.dae"/>
      </geometry>
    </collision>
  </link>

  <joint name="panda_joint7" type="revolute">
    <safety_controller k_position="100.0" k_velocity="40.0" soft_lower_limit="-2.8973" soft_upper_limit="2.8973"/>
    <origin rpy="1.57079632679 0 0" xyz="0.088 0 0"/>
    <parent link="panda_link6"/>
    <child link="panda_link7"/>
    <axis xyz="0 0 1"/>
    <limit effort="12" lower="-2.8973" upper="2.8973" velocity="2.6100"/>
  </joint>

  <link name="panda_link8"/>
  <joint name="panda_joint8" type="fixed">
    <origin rpy="0 0 0" xyz="0 0 0.107"/>
    <parent link="panda_link7"/>
    <child link="panda_link8"/>
  </joint>
  <joint name="panda_hand_joint" type="fixed">
    <parent link="panda_link8"/>
    <child link="panda_hand"/>
    <origin rpy="0 0 -0.785398163397" xyz="0 0 0"/>
  </joint>
  <link name="panda_hand">
    <visual>
      <geometry>
        <mesh filename="package://pybullet_simulator/robots/franka/urdf/meshes/visual/hand.dae"/>
      </geometry>
    </visual>
    <collision>
      <origin rpy="0 0 0" xyz="0 0.0 0"/>
      <geometry>
        <mesh filename="package://pybullet_simulator/robots/franka/urdf/meshes/visual/hand.dae"/>
      </geometry>
    </collision>
  </link>

  <link name="panda_leftfinger">
    <visual>
      <geometry>
        <mesh filename="package://pybullet_simulator/robots/franka/urdf/meshes/visual/finger.dae"/>
      </geometry>
    </visual>
    <collision>
      <geometry>
        <mesh filename="package://pybullet_simulator/robots/franka/urdf/meshes/visual/finger.dae"/>
      </geometry>
    </collision>
  </link>
  <link name="panda_rightfinger">
    <visual>
      <origin rpy="0 0 3.14159265359" xyz="0 0 0"/>
      <geometry>
        <mesh filename="package://pybullet_simulator/robots/franka/urdf/meshes/visual/finger.dae"/>
      </geometry>
    </visual>
    <collision>
      <origin rpy="0 0 3.14159265359" xyz="0 0 0"/>
      <geometry>
        <mesh filename="package://pybullet_simulator/robots/franka/urdf/meshes/visual/finger.dae"/>
      </geometry>
    </collision>
  </link>
  <joint name="panda_finger_joint1" type="prismatic">
    <parent link="panda_hand"/>
    <child link="panda_leftfinger"/>
    <origin rpy="0 0 0" xyz="0 0 0.0584"/>
    <axis xyz="0 1 0"/>
    <limit effort="20" lower="0.0" upper="0.04" velocity="0.2"/>
  </joint>
  <joint name="panda_finger_joint2" type="prismatic">
    <parent link="panda_hand"/>
    <child link="panda_rightfinger"/>
    <origin rpy="0 0 0" xyz="0 0 0.0584"/>
    <axis xyz="0 -1 0"/>
    <limit effort="20" lower="0.0" upper="0.04" velocity="0.2"/>
    <mimic joint="panda_finger_joint1"/>
  </joint>

  <joint name="realsense_camera_joint" type="fixed">
    <origin rpy="-0.348 -1.564 -2.784" xyz="0.051 -0.019 0.059"/>
    <parent link="panda_hand"/>
    <child link="realsense_link"/>
  </joint>

  <link name="realsense_link">
    <visual>
      <!-- the mesh origin is at front plate in between the two infrared camera axes -->
      <origin rpy="1.57079632679 0 1.57079632679" xyz="0.0 -0.0 0"/>
      <geometry>
        <!-- <box size="${d435_cam_width} ${d435_cam_height} ${d435_cam_depth}"/> -->
        <mesh filename="package://pybullet_simulator/robots/franka/urdf/meshes/visual/d435.obj"/>
      </geometry>
      <material name="DarkGrey">
        <color rgba="0.3 0.3 0.3 1.0"/>
      </material>
    </visual>
    <collision>
      <origin rpy="0 0 0" xyz="0 -0.0175 0"/>
      <geometry>
        <box size="0.02505 0.09 0.025"/>
      </geometry>
    </collision>
    <inertial>
      <!-- The following are not reliable values, and should not be used for modeling -->
      <mass value="0.072"/>
      <origin xyz="0 0 0"/>
      <inertia ixx="0.003881243" ixy="0.0" ixz="0.0" iyy="0.000498940" iyz="0.0" izz="0.003879257"/>
    </inertial>
  </link>

  <joint name="realsense_optical_joint" type="fixed">
    <origin rpy="-1.571 0 -1.571" xyz="0.0 0.015 0.0"/>
    <parent link="realsense_link"/>
    <child link="realsense_color_optical_frame"/>
  </joint>

  <joint name="realsense_fake_joint" type="fixed">
    <origin rpy="0.0 0.0 0.0" xyz="0.0 0.015 0.0"/>
    <parent link="realsense_link"/>
    <child link="realsense_camera_frame"/>
  </joint>

  <link name="realsense_camera_frame">
    <inertial>
      <mass value="1e-6"/>
      <origin rpy="0 0 0" xyz="0.0 0.0 0.0"/>
      <inertia ixx="1e-6" ixy="0.0" ixz="0.0" iyy="1e-6" iyz="0.0" izz="1e-6"/>
    </inertial>
  </link>

  <link name="realsense_color_optical_frame">
    <inertial>
      <mass value="1e-6"/>
      <origin rpy="0 0 0" xyz="0.0 0.0 0.0"/>
      <inertia ixx="1e-6" ixy="0.0" ixz="0.0" iyy="1e-6" iyz="0.0" izz="1e-6"/>
    </inertial>
  </link>

  <joint name="realsense_rgb2depth_virtual_joint" type="fixed">
    <origin rpy="0.0 0.0 0.0" xyz="0.0 0.0 0.0"/>
    <parent link="realsense_color_optical_frame"/>
    <child link="realsense_depth_optical_frame"/>
  </joint>

  <link name="realsense_depth_optical_frame"></link>

  <joint name="panda_hand_to_tool" type="fixed">
    <origin rpy="-0 0 0" xyz="0.0 0.0 0.145"/>
    <parent link="panda_hand"/>
    <child link="tool"/>
  </joint>

  <link name="tool">
    <inertial>
      <mass value="1e-6"/>
      <origin rpy="0 0 0" xyz="0.0 0.0 0.0"/>
      <inertia ixx="1e-6" ixy="0.0" ixz="0.0" iyy="1e-6" iyz="0.0" izz="1e-6"/>
    </inertial>
  </link>

  <joint name="world_link" type="fixed">
    <origin rpy="0.0 0.0 0.0" xyz="0.42 0.0 0.0"/>
    <parent link="panda_link0"/>
    <child link="world"/>
  </joint>

  <link name="world"></link>

  <material name="grey">
    <color rgba="0.8 0.8 0.8 1"/>
  </material>

  <link name="table">
    <visual>
      <geometry>
        <mesh filename="package://pybullet_simulator/robots/franka/urdf/meshes/visual/table.dae"/>
      </geometry>
      <material name="grey"/>
    </visual>
    <collision>
      <geometry>
        <mesh filename="package://pybullet_simulator/robots/franka/urdf/meshes/visual/table.obj"/>
      </geometry>
    </collision>
  </link>

  <joint name="table_joint" type="fixed">
    <parent link="world"/>
    <child link="table"/>
    <origin xyz="0.0 0.0 -0.39" rpy="0.0 0.0 0.0"/>
  </joint>

  <joint name="panda_ee_link_joint" type="fixed">
    <origin rpy="0.0 0.0 -0.785" xyz="0.0 0.0 0.15"/>
    <parent link="panda_link8"/>
    <child link="panda_ee_link"/>
  </joint>

  <link name="panda_ee_link"></link>
  <!-- If the transformation is changed, the transformation should also be modifiedin ros_interface.py -->
  <joint name="kinect_camera_joint" type="fixed">
    <origin rpy="0.013071139211061986 0.5349760001576646 3.1415926535897" xyz="1.336 0.006 0.692"/>
    <parent link="panda_link0"/>
    <child link="opengl_rgb_camera_link"/>
  </joint>

  <link name="opengl_rgb_camera_link"></link>

  <joint name="kinect_opengl_virtual_joint" type="fixed">
    <origin rpy="-1.571 0 -1.571" xyz="0.0 0.0 0.0"/>
    <parent link="opengl_rgb_camera_link"/>
    <child link="rgb_camera_link"/>
  </joint>

  <link name="rgb_camera_link"></link>

  <joint name="kinect_rgb2depth_virtual_joint" type="fixed">
    <origin rpy="0.0 0.0 0.0" xyz="0.0 0.0 0.0"/>
    <parent link="rgb_camera_link"/>
    <child link="depth_camera_link"/>
  </joint>
  <link name="depth_camera_link"></link>
</robot>

